I'm sorry, but an uncaught exception occurred.

While running game code:
  File "game/second_scene.rpy", line 217, in script
    
Exception: Sayer 'nn' is not defined.

-- Full Traceback ------------------------------------------------------------

Full traceback:
  File "game/second_scene.rpy", line 217, in script
    
  File "C:\Users\Denis\Quasidisk D\Tools\RenPy\renpy-8.1.3-sdk\renpy\ast.py", line 890, in execute
    who = eval_who(self.who, self.who_fast)
  File "C:\Users\Denis\Quasidisk D\Tools\RenPy\renpy-8.1.3-sdk\renpy\ast.py", line 783, in eval_who
    raise Exception("Sayer '%s' is not defined." % who)
Exception: Sayer 'nn' is not defined.

Windows-10-10.0.22621 AMD64
Ren'Py 8.1.4.23121702+nightly
Ночь перед экзаменом 1.0
Sat Dec 30 19:39:08 2023
